{
    DataVersion: 3465,
    size: [11, 7, 11],
    data: [
        {pos: [1, 1, 1], state: "minecraft:glass"},
        {pos: [1, 1, 2], state: "minecraft:white_stained_glass"},
        {pos: [1, 1, 3], state: "minecraft:white_stained_glass"},
        {pos: [1, 1, 4], state: "minecraft:white_stained_glass"},
        {pos: [1, 1, 5], state: "minecraft:white_stained_glass"},
        {pos: [1, 1, 6], state: "minecraft:white_stained_glass"},
        {pos: [1, 1, 7], state: "minecraft:white_stained_glass"},
        {pos: [1, 1, 8], state: "minecraft:white_stained_glass"},
        {pos: [1, 1, 9], state: "minecraft:glass"},
        {pos: [2, 1, 1], state: "minecraft:white_stained_glass"},
        {pos: [2, 1, 2], state: "minecraft:glass"},
        {pos: [2, 1, 3], state: "minecraft:glass"},
        {pos: [2, 1, 4], state: "minecraft:glass"},
        {pos: [2, 1, 5], state: "minecraft:glass"},
        {pos: [2, 1, 6], state: "minecraft:glass"},
        {pos: [2, 1, 7], state: "minecraft:glass"},
        {pos: [2, 1, 8], state: "minecraft:glass"},
        {pos: [2, 1, 9], state: "minecraft:white_stained_glass"},
        {pos: [3, 1, 1], state: "minecraft:white_stained_glass"},
        {pos: [3, 1, 2], state: "minecraft:glass"},
        {pos: [3, 1, 3], state: "minecraft:cobblestone"},
        {pos: [3, 1, 4], state: "minecraft:glass"},
        {pos: [3, 1, 5], state: "minecraft:glass"},
        {pos: [3, 1, 6], state: "minecraft:glass"},
        {pos: [3, 1, 7], state: "minecraft:cobblestone"},
        {pos: [3, 1, 8], state: "minecraft:glass"},
        {pos: [3, 1, 9], state: "minecraft:white_stained_glass"},
        {pos: [4, 1, 1], state: "minecraft:white_stained_glass"},
        {pos: [4, 1, 2], state: "minecraft:glass"},
        {pos: [4, 1, 3], state: "minecraft:glass"},
        {pos: [4, 1, 4], state: "minecraft:grass_block{snowy:false}"},
        {pos: [4, 1, 5], state: "minecraft:grass_block{snowy:false}"},
        {pos: [4, 1, 6], state: "minecraft:grass_block{snowy:false}"},
        {pos: [4, 1, 7], state: "minecraft:glass"},
        {pos: [4, 1, 8], state: "minecraft:glass"},
        {pos: [4, 1, 9], state: "minecraft:white_stained_glass"},
        {pos: [5, 1, 1], state: "minecraft:white_stained_glass"},
        {pos: [5, 1, 2], state: "minecraft:glass"},
        {pos: [5, 1, 3], state: "minecraft:glass"},
        {pos: [5, 1, 4], state: "minecraft:grass_block{snowy:false}"},
        {pos: [5, 1, 5], state: "minecraft:grass_block{snowy:false}"},
        {pos: [5, 1, 6], state: "minecraft:grass_block{snowy:false}"},
        {pos: [5, 1, 7], state: "minecraft:glass"},
        {pos: [5, 1, 8], state: "minecraft:glass"},
        {pos: [5, 1, 9], state: "minecraft:white_stained_glass"},
        {pos: [6, 1, 1], state: "minecraft:white_stained_glass"},
        {pos: [6, 1, 2], state: "minecraft:glass"},
        {pos: [6, 1, 3], state: "minecraft:glass"},
        {pos: [6, 1, 4], state: "minecraft:grass_block{snowy:false}"},
        {pos: [6, 1, 5], state: "minecraft:grass_block{snowy:false}"},
        {pos: [6, 1, 6], state: "minecraft:grass_block{snowy:false}"},
        {pos: [6, 1, 7], state: "minecraft:glass"},
        {pos: [6, 1, 8], state: "minecraft:glass"},
        {pos: [6, 1, 9], state: "minecraft:white_stained_glass"},
        {pos: [7, 1, 1], state: "minecraft:white_stained_glass"},
        {pos: [7, 1, 2], state: "minecraft:glass"},
        {pos: [7, 1, 3], state: "minecraft:cobblestone"},
        {pos: [7, 1, 4], state: "minecraft:glass"},
        {pos: [7, 1, 5], state: "minecraft:glass"},
        {pos: [7, 1, 6], state: "minecraft:glass"},
        {pos: [7, 1, 7], state: "minecraft:cobblestone"},
        {pos: [7, 1, 8], state: "minecraft:glass"},
        {pos: [7, 1, 9], state: "minecraft:white_stained_glass"},
        {pos: [8, 1, 1], state: "minecraft:white_stained_glass"},
        {pos: [8, 1, 2], state: "minecraft:glass"},
        {pos: [8, 1, 3], state: "minecraft:glass"},
        {pos: [8, 1, 4], state: "minecraft:glass"},
        {pos: [8, 1, 5], state: "minecraft:glass"},
        {pos: [8, 1, 6], state: "minecraft:glass"},
        {pos: [8, 1, 7], state: "minecraft:glass"},
        {pos: [8, 1, 8], state: "minecraft:glass"},
        {pos: [8, 1, 9], state: "minecraft:white_stained_glass"},
        {pos: [9, 1, 1], state: "minecraft:glass"},
        {pos: [9, 1, 2], state: "minecraft:white_stained_glass"},
        {pos: [9, 1, 3], state: "minecraft:white_stained_glass"},
        {pos: [9, 1, 4], state: "minecraft:white_stained_glass"},
        {pos: [9, 1, 5], state: "minecraft:white_stained_glass"},
        {pos: [9, 1, 6], state: "minecraft:white_stained_glass"},
        {pos: [9, 1, 7], state: "minecraft:white_stained_glass"},
        {pos: [9, 1, 8], state: "minecraft:white_stained_glass"},
        {pos: [9, 1, 9], state: "minecraft:glass"},
        {pos: [1, 2, 1], state: "minecraft:glass"},
        {pos: [1, 2, 2], state: "minecraft:red_stained_glass_pane{east:false,north:true,south:true,waterlogged:false,west:false}"},
        {pos: [1, 2, 3], state: "minecraft:red_stained_glass_pane{east:false,north:true,south:true,waterlogged:false,west:false}"},
        {pos: [1, 2, 4], state: "minecraft:red_stained_glass_pane{east:false,north:true,south:true,waterlogged:false,west:false}"},
        {pos: [1, 2, 5], state: "minecraft:red_stained_glass_pane{east:false,north:true,south:true,waterlogged:false,west:false}"},
        {pos: [1, 2, 6], state: "minecraft:red_stained_glass_pane{east:false,north:true,south:true,waterlogged:false,west:false}"},
        {pos: [1, 2, 7], state: "minecraft:red_stained_glass_pane{east:false,north:true,south:true,waterlogged:false,west:false}"},
        {pos: [1, 2, 8], state: "minecraft:red_stained_glass_pane{east:false,north:true,south:true,waterlogged:false,west:false}"},
        {pos: [1, 2, 9], state: "minecraft:glass"},
        {pos: [2, 2, 1], state: "minecraft:red_stained_glass_pane{east:true,north:false,south:false,waterlogged:false,west:true}"},
        {pos: [2, 2, 9], state: "minecraft:red_stained_glass_pane{east:true,north:false,south:false,waterlogged:false,west:true}"},
        {pos: [3, 2, 1], state: "minecraft:red_stained_glass_pane{east:true,north:false,south:false,waterlogged:false,west:true}"},
        {pos: [3, 2, 9], state: "minecraft:red_stained_glass_pane{east:true,north:false,south:false,waterlogged:false,west:true}"},
        {pos: [4, 2, 1], state: "minecraft:red_stained_glass_pane{east:true,north:false,south:false,waterlogged:false,west:true}"},
        {pos: [4, 2, 9], state: "minecraft:red_stained_glass_pane{east:true,north:false,south:false,waterlogged:false,west:true}"},
        {pos: [5, 2, 1], state: "minecraft:red_stained_glass_pane{east:true,north:false,south:false,waterlogged:false,west:true}"},
        {pos: [5, 2, 9], state: "minecraft:red_stained_glass_pane{east:true,north:false,south:false,waterlogged:false,west:true}"},
        {pos: [6, 2, 1], state: "minecraft:red_stained_glass_pane{east:true,north:false,south:false,waterlogged:false,west:true}"},
        {pos: [6, 2, 9], state: "minecraft:red_stained_glass_pane{east:true,north:false,south:false,waterlogged:false,west:true}"},
        {pos: [7, 2, 1], state: "minecraft:red_stained_glass_pane{east:true,north:false,south:false,waterlogged:false,west:true}"},
        {pos: [7, 2, 9], state: "minecraft:red_stained_glass_pane{east:true,north:false,south:false,waterlogged:false,west:true}"},
        {pos: [8, 2, 1], state: "minecraft:red_stained_glass_pane{east:true,north:false,south:false,waterlogged:false,west:true}"},
        {pos: [8, 2, 9], state: "minecraft:red_stained_glass_pane{east:true,north:false,south:false,waterlogged:false,west:true}"},
        {pos: [9, 2, 1], state: "minecraft:glass"},
        {pos: [9, 2, 2], state: "minecraft:red_stained_glass_pane{east:false,north:true,south:true,waterlogged:false,west:false}"},
        {pos: [9, 2, 3], state: "minecraft:red_stained_glass_pane{east:false,north:true,south:true,waterlogged:false,west:false}"},
        {pos: [9, 2, 4], state: "minecraft:red_stained_glass_pane{east:false,north:true,south:true,waterlogged:false,west:false}"},
        {pos: [9, 2, 5], state: "minecraft:red_stained_glass_pane{east:false,north:true,south:true,waterlogged:false,west:false}"},
        {pos: [9, 2, 6], state: "minecraft:red_stained_glass_pane{east:false,north:true,south:true,waterlogged:false,west:false}"},
        {pos: [9, 2, 7], state: "minecraft:red_stained_glass_pane{east:false,north:true,south:true,waterlogged:false,west:false}"},
        {pos: [9, 2, 8], state: "minecraft:red_stained_glass_pane{east:false,north:true,south:true,waterlogged:false,west:false}"},
        {pos: [9, 2, 9], state: "minecraft:glass"},
        {pos: [1, 3, 1], state: "minecraft:glass"},
        {pos: [1, 3, 2], state: "minecraft:red_stained_glass_pane{east:false,north:true,south:true,waterlogged:false,west:false}"},
        {pos: [1, 3, 3], state: "minecraft:red_stained_glass_pane{east:false,north:true,south:true,waterlogged:false,west:false}"},
        {pos: [1, 3, 4], state: "minecraft:red_stained_glass_pane{east:false,north:true,south:true,waterlogged:false,west:false}"},
        {pos: [1, 3, 5], state: "minecraft:red_stained_glass_pane{east:false,north:true,south:true,waterlogged:false,west:false}"},
        {pos: [1, 3, 6], state: "minecraft:red_stained_glass_pane{east:false,north:true,south:true,waterlogged:false,west:false}"},
        {pos: [1, 3, 7], state: "minecraft:red_stained_glass_pane{east:false,north:true,south:true,waterlogged:false,west:false}"},
        {pos: [1, 3, 8], state: "minecraft:red_stained_glass_pane{east:false,north:true,south:true,waterlogged:false,west:false}"},
        {pos: [1, 3, 9], state: "minecraft:glass"},
        {pos: [2, 3, 1], state: "minecraft:red_stained_glass_pane{east:true,north:false,south:false,waterlogged:false,west:true}"},
        {pos: [2, 3, 9], state: "minecraft:red_stained_glass_pane{east:true,north:false,south:false,waterlogged:false,west:true}"},
        {pos: [3, 3, 1], state: "minecraft:red_stained_glass_pane{east:true,north:false,south:false,waterlogged:false,west:true}"},
        {pos: [3, 3, 9], state: "minecraft:red_stained_glass_pane{east:true,north:false,south:false,waterlogged:false,west:true}"},
        {pos: [4, 3, 1], state: "minecraft:red_stained_glass_pane{east:true,north:false,south:false,waterlogged:false,west:true}"},
        {pos: [4, 3, 9], state: "minecraft:red_stained_glass_pane{east:true,north:false,south:false,waterlogged:false,west:true}"},
        {pos: [5, 3, 1], state: "minecraft:red_stained_glass_pane{east:true,north:false,south:false,waterlogged:false,west:true}"},
        {pos: [5, 3, 9], state: "minecraft:red_stained_glass_pane{east:true,north:false,south:false,waterlogged:false,west:true}"},
        {pos: [6, 3, 1], state: "minecraft:red_stained_glass_pane{east:true,north:false,south:false,waterlogged:false,west:true}"},
        {pos: [6, 3, 9], state: "minecraft:red_stained_glass_pane{east:true,north:false,south:false,waterlogged:false,west:true}"},
        {pos: [7, 3, 1], state: "minecraft:red_stained_glass_pane{east:true,north:false,south:false,waterlogged:false,west:true}"},
        {pos: [7, 3, 9], state: "minecraft:red_stained_glass_pane{east:true,north:false,south:false,waterlogged:false,west:true}"},
        {pos: [8, 3, 1], state: "minecraft:red_stained_glass_pane{east:true,north:false,south:false,waterlogged:false,west:true}"},
        {pos: [8, 3, 9], state: "minecraft:red_stained_glass_pane{east:true,north:false,south:false,waterlogged:false,west:true}"},
        {pos: [9, 3, 1], state: "minecraft:glass"},
        {pos: [9, 3, 2], state: "minecraft:red_stained_glass_pane{east:false,north:true,south:true,waterlogged:false,west:false}"},
        {pos: [9, 3, 3], state: "minecraft:red_stained_glass_pane{east:false,north:true,south:true,waterlogged:false,west:false}"},
        {pos: [9, 3, 4], state: "minecraft:red_stained_glass_pane{east:false,north:true,south:true,waterlogged:false,west:false}"},
        {pos: [9, 3, 5], state: "minecraft:red_stained_glass_pane{east:false,north:true,south:true,waterlogged:false,west:false}"},
        {pos: [9, 3, 6], state: "minecraft:red_stained_glass_pane{east:false,north:true,south:true,waterlogged:false,west:false}"},
        {pos: [9, 3, 7], state: "minecraft:red_stained_glass_pane{east:false,north:true,south:true,waterlogged:false,west:false}"},
        {pos: [9, 3, 8], state: "minecraft:red_stained_glass_pane{east:false,north:true,south:true,waterlogged:false,west:false}"},
        {pos: [9, 3, 9], state: "minecraft:glass"},
        {pos: [1, 4, 1], state: "minecraft:redstone_lamp{lit:false}"},
        {pos: [1, 4, 9], state: "minecraft:redstone_lamp{lit:false}"},
        {pos: [9, 4, 1], state: "minecraft:redstone_lamp{lit:false}"},
        {pos: [9, 4, 9], state: "minecraft:redstone_lamp{lit:false}"},
        {pos: [1, 5, 1], state: "minecraft:daylight_detector{inverted:true,power:0}", nbt: {ForgeCaps: {}, id: "minecraft:daylight_detector"}},
        {pos: [1, 5, 9], state: "minecraft:daylight_detector{inverted:true,power:0}", nbt: {ForgeCaps: {}, id: "minecraft:daylight_detector"}},
        {pos: [9, 5, 1], state: "minecraft:daylight_detector{inverted:true,power:0}", nbt: {ForgeCaps: {}, id: "minecraft:daylight_detector"}},
        {pos: [9, 5, 9], state: "minecraft:daylight_detector{inverted:true,power:0}", nbt: {ForgeCaps: {}, id: "minecraft:daylight_detector"}}
    ],
    entities: [],
    palette: [
        "minecraft:glass",
        "minecraft:white_stained_glass",
        "minecraft:cobblestone",
        "minecraft:grass_block{snowy:false}",
        "minecraft:redstone_lamp{lit:false}",
        "minecraft:red_stained_glass_pane{east:false,north:true,south:true,waterlogged:false,west:false}",
        "minecraft:red_stained_glass_pane{east:true,north:false,south:false,waterlogged:false,west:true}",
        "minecraft:daylight_detector{inverted:true,power:0}"
    ]
}